[Fri Nov 01 22:49:00.302635 2024] [wsgi:error] [pid 22222] [remote 78.153.140.224:59228] mod_wsgi (pid=22222): Failed to exec Python script file '/var/www/bdatalab/bdatalab.wsgi'.
[Fri Nov 01 22:49:00.302699 2024] [wsgi:error] [pid 22222] [remote 78.153.140.224:59228] mod_wsgi (pid=22222): Exception occurred processing WSGI script '/var/www/bdatalab/bdatalab.wsgi'.
[Fri Nov 01 22:49:00.303362 2024] [wsgi:error] [pid 22222] [remote 78.153.140.224:59228] Traceback (most recent call last):
[Fri Nov 01 22:49:00.303480 2024] [wsgi:error] [pid 22222] [remote 78.153.140.224:59228]   File "/var/www/bdatalab/bdatalab.wsgi", line 9, in <module>
[Fri Nov 01 22:49:00.303486 2024] [wsgi:error] [pid 22222] [remote 78.153.140.224:59228]     application = create_app()
[Fri Nov 01 22:49:00.303488 2024] [wsgi:error] [pid 22222] [remote 78.153.140.224:59228]                   ^^^^^^^^^^^^
[Fri Nov 01 22:49:00.303497 2024] [wsgi:error] [pid 22222] [remote 78.153.140.224:59228]   File "/var/www/bdatalab/app/__init__.py", line 9, in create_app
[Fri Nov 01 22:49:00.303500 2024] [wsgi:error] [pid 22222] [remote 78.153.140.224:59228]     from .routes.main import main_bp
[Fri Nov 01 22:49:00.303514 2024] [wsgi:error] [pid 22222] [remote 78.153.140.224:59228] ImportError: cannot import name 'main_bp' from 'app.routes.main' (/var/www/bdatalab/app/routes/main.py)
[Fri Nov 01 22:49:01.490868 2024] [wsgi:error] [pid 22222] [remote 78.153.140.224:48170] mod_wsgi (pid=22222): Failed to exec Python script file '/var/www/bdatalab/bdatalab.wsgi'.
[Fri Nov 01 22:49:01.490943 2024] [wsgi:error] [pid 22222] [remote 78.153.140.224:48170] mod_wsgi (pid=22222): Exception occurred processing WSGI script '/var/www/bdatalab/bdatalab.wsgi'.
[Fri Nov 01 22:49:01.491562 2024] [wsgi:error] [pid 22222] [remote 78.153.140.224:48170] Traceback (most recent call last):
[Fri Nov 01 22:49:01.491694 2024] [wsgi:error] [pid 22222] [remote 78.153.140.224:48170]   File "/var/www/bdatalab/bdatalab.wsgi", line 9, in <module>
[Fri Nov 01 22:49:01.491702 2024] [wsgi:error] [pid 22222] [remote 78.153.140.224:48170]     application = create_app()
[Fri Nov 01 22:49:01.491705 2024] [wsgi:error] [pid 22222] [remote 78.153.140.224:48170]                   ^^^^^^^^^^^^
[Fri Nov 01 22:49:01.491716 2024] [wsgi:error] [pid 22222] [remote 78.153.140.224:48170]   File "/var/www/bdatalab/app/__init__.py", line 9, in create_app
[Fri Nov 01 22:49:01.491719 2024] [wsgi:error] [pid 22222] [remote 78.153.140.224:48170]     from .routes.main import main_bp
[Fri Nov 01 22:49:01.491738 2024] [wsgi:error] [pid 22222] [remote 78.153.140.224:48170] ImportError: cannot import name 'main_bp' from 'app.routes.main' (/var/www/bdatalab/app/routes/main.py)
[Fri Nov 01 22:49:02.773328 2024] [wsgi:error] [pid 22222] [remote 78.153.140.224:32932] mod_wsgi (pid=22222): Failed to exec Python script file '/var/www/bdatalab/bdatalab.wsgi'.
[Fri Nov 01 22:49:02.773390 2024] [wsgi:error] [pid 22222] [remote 78.153.140.224:32932] mod_wsgi (pid=22222): Exception occurred processing WSGI script '/var/www/bdatalab/bdatalab.wsgi'.
[Fri Nov 01 22:49:02.774068 2024] [wsgi:error] [pid 22222] [remote 78.153.140.224:32932] Traceback (most recent call last):
[Fri Nov 01 22:49:02.774187 2024] [wsgi:error] [pid 22222] [remote 78.153.140.224:32932]   File "/var/www/bdatalab/bdatalab.wsgi", line 9, in <module>
[Fri Nov 01 22:49:02.774193 2024] [wsgi:error] [pid 22222] [remote 78.153.140.224:32932]     application = create_app()
[Fri Nov 01 22:49:02.774196 2024] [wsgi:error] [pid 22222] [remote 78.153.140.224:32932]                   ^^^^^^^^^^^^
[Fri Nov 01 22:49:02.774204 2024] [wsgi:error] [pid 22222] [remote 78.153.140.224:32932]   File "/var/www/bdatalab/app/__init__.py", line 9, in create_app
[Fri Nov 01 22:49:02.774208 2024] [wsgi:error] [pid 22222] [remote 78.153.140.224:32932]     from .routes.main import main_bp
[Fri Nov 01 22:49:02.774221 2024] [wsgi:error] [pid 22222] [remote 78.153.140.224:32932] ImportError: cannot import name 'main_bp' from 'app.routes.main' (/var/www/bdatalab/app/routes/main.py)
[Fri Nov 01 22:49:04.118282 2024] [wsgi:error] [pid 22222] [remote 78.153.140.224:48628] mod_wsgi (pid=22222): Failed to exec Python script file '/var/www/bdatalab/bdatalab.wsgi'.
[Fri Nov 01 22:49:04.118348 2024] [wsgi:error] [pid 22222] [remote 78.153.140.224:48628] mod_wsgi (pid=22222): Exception occurred processing WSGI script '/var/www/bdatalab/bdatalab.wsgi'.
[Fri Nov 01 22:49:04.118838 2024] [wsgi:error] [pid 22222] [remote 78.153.140.224:48628] Traceback (most recent call last):
[Fri Nov 01 22:49:04.118937 2024] [wsgi:error] [pid 22222] [remote 78.153.140.224:48628]   File "/var/www/bdatalab/bdatalab.wsgi", line 9, in <module>
[Fri Nov 01 22:49:04.118942 2024] [wsgi:error] [pid 22222] [remote 78.153.140.224:48628]     application = create_app()
[Fri Nov 01 22:49:04.118945 2024] [wsgi:error] [pid 22222] [remote 78.153.140.224:48628]                   ^^^^^^^^^^^^
[Fri Nov 01 22:49:04.118952 2024] [wsgi:error] [pid 22222] [remote 78.153.140.224:48628]   File "/var/www/bdatalab/app/__init__.py", line 9, in create_app
[Fri Nov 01 22:49:04.118955 2024] [wsgi:error] [pid 22222] [remote 78.153.140.224:48628]     from .routes.main import main_bp
[Fri Nov 01 22:49:04.118968 2024] [wsgi:error] [pid 22222] [remote 78.153.140.224:48628] ImportError: cannot import name 'main_bp' from 'app.routes.main' (/var/www/bdatalab/app/routes/main.py)
[Fri Nov 01 22:49:05.971745 2024] [wsgi:error] [pid 22222] [remote 78.153.140.224:34830] mod_wsgi (pid=22222): Failed to exec Python script file '/var/www/bdatalab/bdatalab.wsgi'.
[Fri Nov 01 22:49:05.971830 2024] [wsgi:error] [pid 22222] [remote 78.153.140.224:34830] mod_wsgi (pid=22222): Exception occurred processing WSGI script '/var/www/bdatalab/bdatalab.wsgi'.
[Fri Nov 01 22:49:05.972320 2024] [wsgi:error] [pid 22222] [remote 78.153.140.224:34830] Traceback (most recent call last):
[Fri Nov 01 22:49:05.972418 2024] [wsgi:error] [pid 22222] [remote 78.153.140.224:34830]   File "/var/www/bdatalab/bdatalab.wsgi", line 9, in <module>
[Fri Nov 01 22:49:05.972441 2024] [wsgi:error] [pid 22222] [remote 78.153.140.224:34830]     application = create_app()
[Fri Nov 01 22:49:05.972446 2024] [wsgi:error] [pid 22222] [remote 78.153.140.224:34830]                   ^^^^^^^^^^^^
[Fri Nov 01 22:49:05.972456 2024] [wsgi:error] [pid 22222] [remote 78.153.140.224:34830]   File "/var/www/bdatalab/app/__init__.py", line 9, in create_app
[Fri Nov 01 22:49:05.972460 2024] [wsgi:error] [pid 22222] [remote 78.153.140.224:34830]     from .routes.main import main_bp
[Fri Nov 01 22:49:05.972475 2024] [wsgi:error] [pid 22222] [remote 78.153.140.224:34830] ImportError: cannot import name 'main_bp' from 'app.routes.main' (/var/www/bdatalab/app/routes/main.py)
[Fri Nov 01 22:49:08.142943 2024] [wsgi:error] [pid 22222] [remote 78.153.140.224:53908] mod_wsgi (pid=22222): Failed to exec Python script file '/var/www/bdatalab/bdatalab.wsgi'.
[Fri Nov 01 22:49:08.142999 2024] [wsgi:error] [pid 22222] [remote 78.153.140.224:53908] mod_wsgi (pid=22222): Exception occurred processing WSGI script '/var/www/bdatalab/bdatalab.wsgi'.
[Fri Nov 01 22:49:08.143509 2024] [wsgi:error] [pid 22222] [remote 78.153.140.224:53908] Traceback (most recent call last):
[Fri Nov 01 22:49:08.143611 2024] [wsgi:error] [pid 22222] [remote 78.153.140.224:53908]   File "/var/www/bdatalab/bdatalab.wsgi", line 9, in <module>
[Fri Nov 01 22:49:08.143618 2024] [wsgi:error] [pid 22222] [remote 78.153.140.224:53908]     application = create_app()
[Fri Nov 01 22:49:08.143623 2024] [wsgi:error] [pid 22222] [remote 78.153.140.224:53908]                   ^^^^^^^^^^^^
[Fri Nov 01 22:49:08.143632 2024] [wsgi:error] [pid 22222] [remote 78.153.140.224:53908]   File "/var/www/bdatalab/app/__init__.py", line 9, in create_app
[Fri Nov 01 22:49:08.143637 2024] [wsgi:error] [pid 22222] [remote 78.153.140.224:53908]     from .routes.main import main_bp
[Fri Nov 01 22:49:08.143651 2024] [wsgi:error] [pid 22222] [remote 78.153.140.224:53908] ImportError: cannot import name 'main_bp' from 'app.routes.main' (/var/www/bdatalab/app/routes/main.py)
[Fri Nov 01 22:49:09.927904 2024] [wsgi:error] [pid 22222] [remote 78.153.140.224:52898] mod_wsgi (pid=22222): Failed to exec Python script file '/var/www/bdatalab/bdatalab.wsgi'.
[Fri Nov 01 22:49:09.927973 2024] [wsgi:error] [pid 22222] [remote 78.153.140.224:52898] mod_wsgi (pid=22222): Exception occurred processing WSGI script '/var/www/bdatalab/bdatalab.wsgi'.
[Fri Nov 01 22:49:09.928517 2024] [wsgi:error] [pid 22222] [remote 78.153.140.224:52898] Traceback (most recent call last):
[Fri Nov 01 22:49:09.928645 2024] [wsgi:error] [pid 22222] [remote 78.153.140.224:52898]   File "/var/www/bdatalab/bdatalab.wsgi", line 9, in <module>
[Fri Nov 01 22:49:09.928653 2024] [wsgi:error] [pid 22222] [remote 78.153.140.224:52898]     application = create_app()
[Fri Nov 01 22:49:09.928656 2024] [wsgi:error] [pid 22222] [remote 78.153.140.224:52898]                   ^^^^^^^^^^^^
[Fri Nov 01 22:49:09.928664 2024] [wsgi:error] [pid 22222] [remote 78.153.140.224:52898]   File "/var/www/bdatalab/app/__init__.py", line 9, in create_app
[Fri Nov 01 22:49:09.928668 2024] [wsgi:error] [pid 22222] [remote 78.153.140.224:52898]     from .routes.main import main_bp
[Fri Nov 01 22:49:09.928681 2024] [wsgi:error] [pid 22222] [remote 78.153.140.224:52898] ImportError: cannot import name 'main_bp' from 'app.routes.main' (/var/www/bdatalab/app/routes/main.py)
[Fri Nov 01 22:56:05.885230 2024] [wsgi:error] [pid 22222] [remote 193.70.113.250:60640] mod_wsgi (pid=22222): Failed to exec Python script file '/var/www/bdatalab/bdatalab.wsgi'.
[Fri Nov 01 22:56:05.885380 2024] [wsgi:error] [pid 22222] [remote 193.70.113.250:60640] mod_wsgi (pid=22222): Exception occurred processing WSGI script '/var/www/bdatalab/bdatalab.wsgi'.
[Fri Nov 01 22:56:05.885984 2024] [wsgi:error] [pid 22222] [remote 193.70.113.250:60640] Traceback (most recent call last):
[Fri Nov 01 22:56:05.886128 2024] [wsgi:error] [pid 22222] [remote 193.70.113.250:60640]   File "/var/www/bdatalab/bdatalab.wsgi", line 9, in <module>
[Fri Nov 01 22:56:05.886136 2024] [wsgi:error] [pid 22222] [remote 193.70.113.250:60640]     application = create_app()
[Fri Nov 01 22:56:05.886140 2024] [wsgi:error] [pid 22222] [remote 193.70.113.250:60640]                   ^^^^^^^^^^^^
[Fri Nov 01 22:56:05.886150 2024] [wsgi:error] [pid 22222] [remote 193.70.113.250:60640]   File "/var/www/bdatalab/app/__init__.py", line 9, in create_app
[Fri Nov 01 22:56:05.886155 2024] [wsgi:error] [pid 22222] [remote 193.70.113.250:60640]     from .blueprints.other_blueprint import other_bp
[Fri Nov 01 22:56:05.886159 2024] [wsgi:error] [pid 22222] [remote 193.70.113.250:60640]     ^^^^^^^^^^^^^^^^^^^^^^^^^^^^^^^^
[Fri Nov 01 22:56:05.886174 2024] [wsgi:error] [pid 22222] [remote 193.70.113.250:60640] ImportError: cannot import name 'main_bp' from 'app.routes.main' (/var/www/bdatalab/app/routes/main.py)
[Fri Nov 01 22:56:10.549548 2024] [wsgi:error] [pid 22222] [remote 193.70.113.250:60908] mod_wsgi (pid=22222): Failed to exec Python script file '/var/www/bdatalab/bdatalab.wsgi'.
[Fri Nov 01 22:56:10.549608 2024] [wsgi:error] [pid 22222] [remote 193.70.113.250:60908] mod_wsgi (pid=22222): Exception occurred processing WSGI script '/var/www/bdatalab/bdatalab.wsgi'.
[Fri Nov 01 22:56:10.550280 2024] [wsgi:error] [pid 22222] [remote 193.70.113.250:60908] Traceback (most recent call last):
[Fri Nov 01 22:56:10.550408 2024] [wsgi:error] [pid 22222] [remote 193.70.113.250:60908]   File "/var/www/bdatalab/bdatalab.wsgi", line 9, in <module>
[Fri Nov 01 22:56:10.550416 2024] [wsgi:error] [pid 22222] [remote 193.70.113.250:60908]     application = create_app()
[Fri Nov 01 22:56:10.550420 2024] [wsgi:error] [pid 22222] [remote 193.70.113.250:60908]                   ^^^^^^^^^^^^
[Fri Nov 01 22:56:10.550430 2024] [wsgi:error] [pid 22222] [remote 193.70.113.250:60908]   File "/var/www/bdatalab/app/__init__.py", line 9, in create_app
[Fri Nov 01 22:56:10.550435 2024] [wsgi:error] [pid 22222] [remote 193.70.113.250:60908]     from .blueprints.other_blueprint import other_bp
[Fri Nov 01 22:56:10.550439 2024] [wsgi:error] [pid 22222] [remote 193.70.113.250:60908]     ^^^^^^^^^^^^^^^^^^^^^^^^^^^^^^^^
[Fri Nov 01 22:56:10.550466 2024] [wsgi:error] [pid 22222] [remote 193.70.113.250:60908] ImportError: cannot import name 'main_bp' from 'app.routes.main' (/var/www/bdatalab/app/routes/main.py)
