[Fri Nov 01 22:49:00.302635 2024] [wsgi:error] [pid 22222] [remote 78.153.140.224:59228] mod_wsgi (pid=22222): Failed to exec Python script file '/var/www/bdatalab/bdatalab.wsgi'.
[Fri Nov 01 22:49:00.302699 2024] [wsgi:error] [pid 22222] [remote 78.153.140.224:59228] mod_wsgi (pid=22222): Exception occurred processing WSGI script '/var/www/bdatalab/bdatalab.wsgi'.
[Fri Nov 01 22:49:00.303362 2024] [wsgi:error] [pid 22222] [remote 78.153.140.224:59228] Traceback (most recent call last):
[Fri Nov 01 22:49:00.303480 2024] [wsgi:error] [pid 22222] [remote 78.153.140.224:59228]   File "/var/www/bdatalab/bdatalab.wsgi", line 9, in <module>
[Fri Nov 01 22:49:00.303486 2024] [wsgi:error] [pid 22222] [remote 78.153.140.224:59228]     application = create_app()
[Fri Nov 01 22:49:00.303488 2024] [wsgi:error] [pid 22222] [remote 78.153.140.224:59228]                   ^^^^^^^^^^^^
[Fri Nov 01 22:49:00.303497 2024] [wsgi:error] [pid 22222] [remote 78.153.140.224:59228]   File "/var/www/bdatalab/app/__init__.py", line 9, in create_app
[Fri Nov 01 22:49:00.303500 2024] [wsgi:error] [pid 22222] [remote 78.153.140.224:59228]     from .routes.main import main_bp
[Fri Nov 01 22:49:00.303514 2024] [wsgi:error] [pid 22222] [remote 78.153.140.224:59228] ImportError: cannot import name 'main_bp' from 'app.routes.main' (/var/www/bdatalab/app/routes/main.py)
[Fri Nov 01 22:49:01.490868 2024] [wsgi:error] [pid 22222] [remote 78.153.140.224:48170] mod_wsgi (pid=22222): Failed to exec Python script file '/var/www/bdatalab/bdatalab.wsgi'.
[Fri Nov 01 22:49:01.490943 2024] [wsgi:error] [pid 22222] [remote 78.153.140.224:48170] mod_wsgi (pid=22222): Exception occurred processing WSGI script '/var/www/bdatalab/bdatalab.wsgi'.
[Fri Nov 01 22:49:01.491562 2024] [wsgi:error] [pid 22222] [remote 78.153.140.224:48170] Traceback (most recent call last):
[Fri Nov 01 22:49:01.491694 2024] [wsgi:error] [pid 22222] [remote 78.153.140.224:48170]   File "/var/www/bdatalab/bdatalab.wsgi", line 9, in <module>
[Fri Nov 01 22:49:01.491702 2024] [wsgi:error] [pid 22222] [remote 78.153.140.224:48170]     application = create_app()
[Fri Nov 01 22:49:01.491705 2024] [wsgi:error] [pid 22222] [remote 78.153.140.224:48170]                   ^^^^^^^^^^^^
[Fri Nov 01 22:49:01.491716 2024] [wsgi:error] [pid 22222] [remote 78.153.140.224:48170]   File "/var/www/bdatalab/app/__init__.py", line 9, in create_app
[Fri Nov 01 22:49:01.491719 2024] [wsgi:error] [pid 22222] [remote 78.153.140.224:48170]     from .routes.main import main_bp
[Fri Nov 01 22:49:01.491738 2024] [wsgi:error] [pid 22222] [remote 78.153.140.224:48170] ImportError: cannot import name 'main_bp' from 'app.routes.main' (/var/www/bdatalab/app/routes/main.py)
[Fri Nov 01 22:49:02.773328 2024] [wsgi:error] [pid 22222] [remote 78.153.140.224:32932] mod_wsgi (pid=22222): Failed to exec Python script file '/var/www/bdatalab/bdatalab.wsgi'.
[Fri Nov 01 22:49:02.773390 2024] [wsgi:error] [pid 22222] [remote 78.153.140.224:32932] mod_wsgi (pid=22222): Exception occurred processing WSGI script '/var/www/bdatalab/bdatalab.wsgi'.
[Fri Nov 01 22:49:02.774068 2024] [wsgi:error] [pid 22222] [remote 78.153.140.224:32932] Traceback (most recent call last):
[Fri Nov 01 22:49:02.774187 2024] [wsgi:error] [pid 22222] [remote 78.153.140.224:32932]   File "/var/www/bdatalab/bdatalab.wsgi", line 9, in <module>
[Fri Nov 01 22:49:02.774193 2024] [wsgi:error] [pid 22222] [remote 78.153.140.224:32932]     application = create_app()
[Fri Nov 01 22:49:02.774196 2024] [wsgi:error] [pid 22222] [remote 78.153.140.224:32932]                   ^^^^^^^^^^^^
[Fri Nov 01 22:49:02.774204 2024] [wsgi:error] [pid 22222] [remote 78.153.140.224:32932]   File "/var/www/bdatalab/app/__init__.py", line 9, in create_app
[Fri Nov 01 22:49:02.774208 2024] [wsgi:error] [pid 22222] [remote 78.153.140.224:32932]     from .routes.main import main_bp
[Fri Nov 01 22:49:02.774221 2024] [wsgi:error] [pid 22222] [remote 78.153.140.224:32932] ImportError: cannot import name 'main_bp' from 'app.routes.main' (/var/www/bdatalab/app/routes/main.py)
[Fri Nov 01 22:49:04.118282 2024] [wsgi:error] [pid 22222] [remote 78.153.140.224:48628] mod_wsgi (pid=22222): Failed to exec Python script file '/var/www/bdatalab/bdatalab.wsgi'.
[Fri Nov 01 22:49:04.118348 2024] [wsgi:error] [pid 22222] [remote 78.153.140.224:48628] mod_wsgi (pid=22222): Exception occurred processing WSGI script '/var/www/bdatalab/bdatalab.wsgi'.
[Fri Nov 01 22:49:04.118838 2024] [wsgi:error] [pid 22222] [remote 78.153.140.224:48628] Traceback (most recent call last):
[Fri Nov 01 22:49:04.118937 2024] [wsgi:error] [pid 22222] [remote 78.153.140.224:48628]   File "/var/www/bdatalab/bdatalab.wsgi", line 9, in <module>
[Fri Nov 01 22:49:04.118942 2024] [wsgi:error] [pid 22222] [remote 78.153.140.224:48628]     application = create_app()
[Fri Nov 01 22:49:04.118945 2024] [wsgi:error] [pid 22222] [remote 78.153.140.224:48628]                   ^^^^^^^^^^^^
[Fri Nov 01 22:49:04.118952 2024] [wsgi:error] [pid 22222] [remote 78.153.140.224:48628]   File "/var/www/bdatalab/app/__init__.py", line 9, in create_app
[Fri Nov 01 22:49:04.118955 2024] [wsgi:error] [pid 22222] [remote 78.153.140.224:48628]     from .routes.main import main_bp
[Fri Nov 01 22:49:04.118968 2024] [wsgi:error] [pid 22222] [remote 78.153.140.224:48628] ImportError: cannot import name 'main_bp' from 'app.routes.main' (/var/www/bdatalab/app/routes/main.py)
[Fri Nov 01 22:49:05.971745 2024] [wsgi:error] [pid 22222] [remote 78.153.140.224:34830] mod_wsgi (pid=22222): Failed to exec Python script file '/var/www/bdatalab/bdatalab.wsgi'.
[Fri Nov 01 22:49:05.971830 2024] [wsgi:error] [pid 22222] [remote 78.153.140.224:34830] mod_wsgi (pid=22222): Exception occurred processing WSGI script '/var/www/bdatalab/bdatalab.wsgi'.
[Fri Nov 01 22:49:05.972320 2024] [wsgi:error] [pid 22222] [remote 78.153.140.224:34830] Traceback (most recent call last):
[Fri Nov 01 22:49:05.972418 2024] [wsgi:error] [pid 22222] [remote 78.153.140.224:34830]   File "/var/www/bdatalab/bdatalab.wsgi", line 9, in <module>
[Fri Nov 01 22:49:05.972441 2024] [wsgi:error] [pid 22222] [remote 78.153.140.224:34830]     application = create_app()
[Fri Nov 01 22:49:05.972446 2024] [wsgi:error] [pid 22222] [remote 78.153.140.224:34830]                   ^^^^^^^^^^^^
[Fri Nov 01 22:49:05.972456 2024] [wsgi:error] [pid 22222] [remote 78.153.140.224:34830]   File "/var/www/bdatalab/app/__init__.py", line 9, in create_app
[Fri Nov 01 22:49:05.972460 2024] [wsgi:error] [pid 22222] [remote 78.153.140.224:34830]     from .routes.main import main_bp
[Fri Nov 01 22:49:05.972475 2024] [wsgi:error] [pid 22222] [remote 78.153.140.224:34830] ImportError: cannot import name 'main_bp' from 'app.routes.main' (/var/www/bdatalab/app/routes/main.py)
[Fri Nov 01 22:49:08.142943 2024] [wsgi:error] [pid 22222] [remote 78.153.140.224:53908] mod_wsgi (pid=22222): Failed to exec Python script file '/var/www/bdatalab/bdatalab.wsgi'.
[Fri Nov 01 22:49:08.142999 2024] [wsgi:error] [pid 22222] [remote 78.153.140.224:53908] mod_wsgi (pid=22222): Exception occurred processing WSGI script '/var/www/bdatalab/bdatalab.wsgi'.
[Fri Nov 01 22:49:08.143509 2024] [wsgi:error] [pid 22222] [remote 78.153.140.224:53908] Traceback (most recent call last):
[Fri Nov 01 22:49:08.143611 2024] [wsgi:error] [pid 22222] [remote 78.153.140.224:53908]   File "/var/www/bdatalab/bdatalab.wsgi", line 9, in <module>
[Fri Nov 01 22:49:08.143618 2024] [wsgi:error] [pid 22222] [remote 78.153.140.224:53908]     application = create_app()
[Fri Nov 01 22:49:08.143623 2024] [wsgi:error] [pid 22222] [remote 78.153.140.224:53908]                   ^^^^^^^^^^^^
[Fri Nov 01 22:49:08.143632 2024] [wsgi:error] [pid 22222] [remote 78.153.140.224:53908]   File "/var/www/bdatalab/app/__init__.py", line 9, in create_app
[Fri Nov 01 22:49:08.143637 2024] [wsgi:error] [pid 22222] [remote 78.153.140.224:53908]     from .routes.main import main_bp
[Fri Nov 01 22:49:08.143651 2024] [wsgi:error] [pid 22222] [remote 78.153.140.224:53908] ImportError: cannot import name 'main_bp' from 'app.routes.main' (/var/www/bdatalab/app/routes/main.py)
[Fri Nov 01 22:49:09.927904 2024] [wsgi:error] [pid 22222] [remote 78.153.140.224:52898] mod_wsgi (pid=22222): Failed to exec Python script file '/var/www/bdatalab/bdatalab.wsgi'.
[Fri Nov 01 22:49:09.927973 2024] [wsgi:error] [pid 22222] [remote 78.153.140.224:52898] mod_wsgi (pid=22222): Exception occurred processing WSGI script '/var/www/bdatalab/bdatalab.wsgi'.
[Fri Nov 01 22:49:09.928517 2024] [wsgi:error] [pid 22222] [remote 78.153.140.224:52898] Traceback (most recent call last):
[Fri Nov 01 22:49:09.928645 2024] [wsgi:error] [pid 22222] [remote 78.153.140.224:52898]   File "/var/www/bdatalab/bdatalab.wsgi", line 9, in <module>
[Fri Nov 01 22:49:09.928653 2024] [wsgi:error] [pid 22222] [remote 78.153.140.224:52898]     application = create_app()
[Fri Nov 01 22:49:09.928656 2024] [wsgi:error] [pid 22222] [remote 78.153.140.224:52898]                   ^^^^^^^^^^^^
[Fri Nov 01 22:49:09.928664 2024] [wsgi:error] [pid 22222] [remote 78.153.140.224:52898]   File "/var/www/bdatalab/app/__init__.py", line 9, in create_app
[Fri Nov 01 22:49:09.928668 2024] [wsgi:error] [pid 22222] [remote 78.153.140.224:52898]     from .routes.main import main_bp
[Fri Nov 01 22:49:09.928681 2024] [wsgi:error] [pid 22222] [remote 78.153.140.224:52898] ImportError: cannot import name 'main_bp' from 'app.routes.main' (/var/www/bdatalab/app/routes/main.py)
[Fri Nov 01 22:56:05.885230 2024] [wsgi:error] [pid 22222] [remote 193.70.113.250:60640] mod_wsgi (pid=22222): Failed to exec Python script file '/var/www/bdatalab/bdatalab.wsgi'.
[Fri Nov 01 22:56:05.885380 2024] [wsgi:error] [pid 22222] [remote 193.70.113.250:60640] mod_wsgi (pid=22222): Exception occurred processing WSGI script '/var/www/bdatalab/bdatalab.wsgi'.
[Fri Nov 01 22:56:05.885984 2024] [wsgi:error] [pid 22222] [remote 193.70.113.250:60640] Traceback (most recent call last):
[Fri Nov 01 22:56:05.886128 2024] [wsgi:error] [pid 22222] [remote 193.70.113.250:60640]   File "/var/www/bdatalab/bdatalab.wsgi", line 9, in <module>
[Fri Nov 01 22:56:05.886136 2024] [wsgi:error] [pid 22222] [remote 193.70.113.250:60640]     application = create_app()
[Fri Nov 01 22:56:05.886140 2024] [wsgi:error] [pid 22222] [remote 193.70.113.250:60640]                   ^^^^^^^^^^^^
[Fri Nov 01 22:56:05.886150 2024] [wsgi:error] [pid 22222] [remote 193.70.113.250:60640]   File "/var/www/bdatalab/app/__init__.py", line 9, in create_app
[Fri Nov 01 22:56:05.886155 2024] [wsgi:error] [pid 22222] [remote 193.70.113.250:60640]     from .blueprints.other_blueprint import other_bp
[Fri Nov 01 22:56:05.886159 2024] [wsgi:error] [pid 22222] [remote 193.70.113.250:60640]     ^^^^^^^^^^^^^^^^^^^^^^^^^^^^^^^^
[Fri Nov 01 22:56:05.886174 2024] [wsgi:error] [pid 22222] [remote 193.70.113.250:60640] ImportError: cannot import name 'main_bp' from 'app.routes.main' (/var/www/bdatalab/app/routes/main.py)
[Fri Nov 01 22:56:10.549548 2024] [wsgi:error] [pid 22222] [remote 193.70.113.250:60908] mod_wsgi (pid=22222): Failed to exec Python script file '/var/www/bdatalab/bdatalab.wsgi'.
[Fri Nov 01 22:56:10.549608 2024] [wsgi:error] [pid 22222] [remote 193.70.113.250:60908] mod_wsgi (pid=22222): Exception occurred processing WSGI script '/var/www/bdatalab/bdatalab.wsgi'.
[Fri Nov 01 22:56:10.550280 2024] [wsgi:error] [pid 22222] [remote 193.70.113.250:60908] Traceback (most recent call last):
[Fri Nov 01 22:56:10.550408 2024] [wsgi:error] [pid 22222] [remote 193.70.113.250:60908]   File "/var/www/bdatalab/bdatalab.wsgi", line 9, in <module>
[Fri Nov 01 22:56:10.550416 2024] [wsgi:error] [pid 22222] [remote 193.70.113.250:60908]     application = create_app()
[Fri Nov 01 22:56:10.550420 2024] [wsgi:error] [pid 22222] [remote 193.70.113.250:60908]                   ^^^^^^^^^^^^
[Fri Nov 01 22:56:10.550430 2024] [wsgi:error] [pid 22222] [remote 193.70.113.250:60908]   File "/var/www/bdatalab/app/__init__.py", line 9, in create_app
[Fri Nov 01 22:56:10.550435 2024] [wsgi:error] [pid 22222] [remote 193.70.113.250:60908]     from .blueprints.other_blueprint import other_bp
[Fri Nov 01 22:56:10.550439 2024] [wsgi:error] [pid 22222] [remote 193.70.113.250:60908]     ^^^^^^^^^^^^^^^^^^^^^^^^^^^^^^^^
[Fri Nov 01 22:56:10.550466 2024] [wsgi:error] [pid 22222] [remote 193.70.113.250:60908] ImportError: cannot import name 'main_bp' from 'app.routes.main' (/var/www/bdatalab/app/routes/main.py)
[Fri Nov 01 23:52:40.858939 2024] [wsgi:error] [pid 23811] [remote 177.93.3.83:58996] mod_wsgi (pid=23811): Failed to exec Python script file '/var/www/bdatalab/bdatalab.wsgi'.
[Fri Nov 01 23:52:40.859050 2024] [wsgi:error] [pid 23811] [remote 177.93.3.83:58996] mod_wsgi (pid=23811): Exception occurred processing WSGI script '/var/www/bdatalab/bdatalab.wsgi'.
[Fri Nov 01 23:52:40.880924 2024] [wsgi:error] [pid 23811] [remote 177.93.3.83:58996] Traceback (most recent call last):
[Fri Nov 01 23:52:40.883309 2024] [wsgi:error] [pid 23811] [remote 177.93.3.83:58996]   File "/var/www/bdatalab/bdatalab.wsgi", line 8, in <module>
[Fri Nov 01 23:52:40.883324 2024] [wsgi:error] [pid 23811] [remote 177.93.3.83:58996]     from app import create_app
[Fri Nov 01 23:52:40.883335 2024] [wsgi:error] [pid 23811] [remote 177.93.3.83:58996]   File "/var/www/bdatalab/app/__init__.py", line 2, in <module>
[Fri Nov 01 23:52:40.883340 2024] [wsgi:error] [pid 23811] [remote 177.93.3.83:58996]     from flask import Flask
[Fri Nov 01 23:52:40.883349 2024] [wsgi:error] [pid 23811] [remote 177.93.3.83:58996]   File "/var/www/bdatalab/venv/lib/python3.12/site-packages/flask/__init__.py", line 5, in <module>
[Fri Nov 01 23:52:40.883354 2024] [wsgi:error] [pid 23811] [remote 177.93.3.83:58996]     from . import json as json
[Fri Nov 01 23:52:40.883363 2024] [wsgi:error] [pid 23811] [remote 177.93.3.83:58996]   File "/var/www/bdatalab/venv/lib/python3.12/site-packages/flask/json/__init__.py", line 6, in <module>
[Fri Nov 01 23:52:40.883368 2024] [wsgi:error] [pid 23811] [remote 177.93.3.83:58996]     from ..globals import current_app
[Fri Nov 01 23:52:40.883376 2024] [wsgi:error] [pid 23811] [remote 177.93.3.83:58996]   File "/var/www/bdatalab/venv/lib/python3.12/site-packages/flask/globals.py", line 6, in <module>
[Fri Nov 01 23:52:40.883381 2024] [wsgi:error] [pid 23811] [remote 177.93.3.83:58996]     from werkzeug.local import LocalProxy
[Fri Nov 01 23:52:40.883390 2024] [wsgi:error] [pid 23811] [remote 177.93.3.83:58996]   File "/var/www/bdatalab/venv/lib/python3.12/site-packages/werkzeug/__init__.py", line 1, in <module>
[Fri Nov 01 23:52:40.883394 2024] [wsgi:error] [pid 23811] [remote 177.93.3.83:58996]     from .serving import run_simple as run_simple
[Fri Nov 01 23:52:40.883403 2024] [wsgi:error] [pid 23811] [remote 177.93.3.83:58996]   File "/var/www/bdatalab/venv/lib/python3.12/site-packages/werkzeug/serving.py", line 33, in <module>
[Fri Nov 01 23:52:40.883408 2024] [wsgi:error] [pid 23811] [remote 177.93.3.83:58996]     from ._internal import _log
[Fri Nov 01 23:52:40.883416 2024] [wsgi:error] [pid 23811] [remote 177.93.3.83:58996]   File "/var/www/bdatalab/venv/lib/python3.12/site-packages/werkzeug/_internal.py", line 3, in <module>
[Fri Nov 01 23:52:40.883421 2024] [wsgi:error] [pid 23811] [remote 177.93.3.83:58996]     import logging
[Fri Nov 01 23:52:40.883437 2024] [wsgi:error] [pid 23811] [remote 177.93.3.83:58996]   File "/var/www/bdatalab/venv/lib/python3.12/site-packages/logging/__init__.py", line 618
[Fri Nov 01 23:52:40.883449 2024] [wsgi:error] [pid 23811] [remote 177.93.3.83:58996]     raise NotImplementedError, 'emit must be implemented '\\
[Fri Nov 01 23:52:40.883466 2024] [wsgi:error] [pid 23811] [remote 177.93.3.83:58996]                              ^
[Fri Nov 01 23:52:40.883476 2024] [wsgi:error] [pid 23811] [remote 177.93.3.83:58996] SyntaxError: invalid syntax
[Fri Nov 01 23:53:05.833666 2024] [wsgi:error] [pid 23811] [remote 65.49.1.35:46303] mod_wsgi (pid=23811): Failed to exec Python script file '/var/www/bdatalab/bdatalab.wsgi'.
[Fri Nov 01 23:53:05.833729 2024] [wsgi:error] [pid 23811] [remote 65.49.1.35:46303] mod_wsgi (pid=23811): Exception occurred processing WSGI script '/var/www/bdatalab/bdatalab.wsgi'.
[Fri Nov 01 23:53:05.833965 2024] [wsgi:error] [pid 23811] [remote 65.49.1.35:46303] Traceback (most recent call last):
[Fri Nov 01 23:53:05.834206 2024] [wsgi:error] [pid 23811] [remote 65.49.1.35:46303]   File "/var/www/bdatalab/bdatalab.wsgi", line 8, in <module>
[Fri Nov 01 23:53:05.834212 2024] [wsgi:error] [pid 23811] [remote 65.49.1.35:46303]     from app import create_app
[Fri Nov 01 23:53:05.834220 2024] [wsgi:error] [pid 23811] [remote 65.49.1.35:46303]   File "/var/www/bdatalab/app/__init__.py", line 2, in <module>
[Fri Nov 01 23:53:05.834223 2024] [wsgi:error] [pid 23811] [remote 65.49.1.35:46303]     from flask import Flask
[Fri Nov 01 23:53:05.834230 2024] [wsgi:error] [pid 23811] [remote 65.49.1.35:46303]   File "/var/www/bdatalab/venv/lib/python3.12/site-packages/flask/__init__.py", line 5, in <module>
[Fri Nov 01 23:53:05.834321 2024] [wsgi:error] [pid 23811] [remote 65.49.1.35:46303]     from . import json as json
[Fri Nov 01 23:53:05.834494 2024] [wsgi:error] [pid 23811] [remote 65.49.1.35:46303]   File "/var/www/bdatalab/venv/lib/python3.12/site-packages/flask/json/__init__.py", line 6, in <module>
[Fri Nov 01 23:53:05.834498 2024] [wsgi:error] [pid 23811] [remote 65.49.1.35:46303]     from ..globals import current_app
[Fri Nov 01 23:53:05.834505 2024] [wsgi:error] [pid 23811] [remote 65.49.1.35:46303]   File "/var/www/bdatalab/venv/lib/python3.12/site-packages/flask/globals.py", line 6, in <module>
[Fri Nov 01 23:53:05.834509 2024] [wsgi:error] [pid 23811] [remote 65.49.1.35:46303]     from werkzeug.local import LocalProxy
[Fri Nov 01 23:53:05.834515 2024] [wsgi:error] [pid 23811] [remote 65.49.1.35:46303]   File "/var/www/bdatalab/venv/lib/python3.12/site-packages/werkzeug/__init__.py", line 1, in <module>
[Fri Nov 01 23:53:05.834518 2024] [wsgi:error] [pid 23811] [remote 65.49.1.35:46303]     from .serving import run_simple as run_simple
[Fri Nov 01 23:53:05.834525 2024] [wsgi:error] [pid 23811] [remote 65.49.1.35:46303]   File "/var/www/bdatalab/venv/lib/python3.12/site-packages/werkzeug/serving.py", line 33, in <module>
[Fri Nov 01 23:53:05.834528 2024] [wsgi:error] [pid 23811] [remote 65.49.1.35:46303]     from ._internal import _log
[Fri Nov 01 23:53:05.834535 2024] [wsgi:error] [pid 23811] [remote 65.49.1.35:46303]   File "/var/www/bdatalab/venv/lib/python3.12/site-packages/werkzeug/_internal.py", line 3, in <module>
[Fri Nov 01 23:53:05.834538 2024] [wsgi:error] [pid 23811] [remote 65.49.1.35:46303]     import logging
[Fri Nov 01 23:53:05.834556 2024] [wsgi:error] [pid 23811] [remote 65.49.1.35:46303]   File "/var/www/bdatalab/venv/lib/python3.12/site-packages/logging/__init__.py", line 618
[Fri Nov 01 23:53:05.834567 2024] [wsgi:error] [pid 23811] [remote 65.49.1.35:46303]     raise NotImplementedError, 'emit must be implemented '\\
[Fri Nov 01 23:53:05.834583 2024] [wsgi:error] [pid 23811] [remote 65.49.1.35:46303]                              ^
[Fri Nov 01 23:53:05.834591 2024] [wsgi:error] [pid 23811] [remote 65.49.1.35:46303] SyntaxError: invalid syntax
[Fri Nov 01 23:59:11.560189 2024] [wsgi:error] [pid 23811] [remote 65.49.1.36:48157] mod_wsgi (pid=23811): Failed to exec Python script file '/var/www/bdatalab/bdatalab.wsgi'.
[Fri Nov 01 23:59:11.560266 2024] [wsgi:error] [pid 23811] [remote 65.49.1.36:48157] mod_wsgi (pid=23811): Exception occurred processing WSGI script '/var/www/bdatalab/bdatalab.wsgi'.
[Fri Nov 01 23:59:11.560561 2024] [wsgi:error] [pid 23811] [remote 65.49.1.36:48157] Traceback (most recent call last):
[Fri Nov 01 23:59:11.560778 2024] [wsgi:error] [pid 23811] [remote 65.49.1.36:48157]   File "/var/www/bdatalab/bdatalab.wsgi", line 8, in <module>
[Fri Nov 01 23:59:11.560787 2024] [wsgi:error] [pid 23811] [remote 65.49.1.36:48157]     from app import create_app
[Fri Nov 01 23:59:11.560797 2024] [wsgi:error] [pid 23811] [remote 65.49.1.36:48157]   File "/var/www/bdatalab/app/__init__.py", line 2, in <module>
[Fri Nov 01 23:59:11.560816 2024] [wsgi:error] [pid 23811] [remote 65.49.1.36:48157]     from flask import Flask
[Fri Nov 01 23:59:11.560828 2024] [wsgi:error] [pid 23811] [remote 65.49.1.36:48157]   File "/var/www/bdatalab/venv/lib/python3.12/site-packages/flask/__init__.py", line 5, in <module>
[Fri Nov 01 23:59:11.560845 2024] [wsgi:error] [pid 23811] [remote 65.49.1.36:48157]     from . import json as json
[Fri Nov 01 23:59:11.560853 2024] [wsgi:error] [pid 23811] [remote 65.49.1.36:48157]   File "/var/www/bdatalab/venv/lib/python3.12/site-packages/flask/json/__init__.py", line 6, in <module>
[Fri Nov 01 23:59:11.560857 2024] [wsgi:error] [pid 23811] [remote 65.49.1.36:48157]     from ..globals import current_app
[Fri Nov 01 23:59:11.560864 2024] [wsgi:error] [pid 23811] [remote 65.49.1.36:48157]   File "/var/www/bdatalab/venv/lib/python3.12/site-packages/flask/globals.py", line 6, in <module>
[Fri Nov 01 23:59:11.560867 2024] [wsgi:error] [pid 23811] [remote 65.49.1.36:48157]     from werkzeug.local import LocalProxy
[Fri Nov 01 23:59:11.560877 2024] [wsgi:error] [pid 23811] [remote 65.49.1.36:48157]   File "/var/www/bdatalab/venv/lib/python3.12/site-packages/werkzeug/__init__.py", line 1, in <module>
[Fri Nov 01 23:59:11.560880 2024] [wsgi:error] [pid 23811] [remote 65.49.1.36:48157]     from .serving import run_simple as run_simple
[Fri Nov 01 23:59:11.560887 2024] [wsgi:error] [pid 23811] [remote 65.49.1.36:48157]   File "/var/www/bdatalab/venv/lib/python3.12/site-packages/werkzeug/serving.py", line 33, in <module>
[Fri Nov 01 23:59:11.560890 2024] [wsgi:error] [pid 23811] [remote 65.49.1.36:48157]     from ._internal import _log
[Fri Nov 01 23:59:11.560897 2024] [wsgi:error] [pid 23811] [remote 65.49.1.36:48157]   File "/var/www/bdatalab/venv/lib/python3.12/site-packages/werkzeug/_internal.py", line 3, in <module>
[Fri Nov 01 23:59:11.560901 2024] [wsgi:error] [pid 23811] [remote 65.49.1.36:48157]     import logging
[Fri Nov 01 23:59:11.560915 2024] [wsgi:error] [pid 23811] [remote 65.49.1.36:48157]   File "/var/www/bdatalab/venv/lib/python3.12/site-packages/logging/__init__.py", line 618
[Fri Nov 01 23:59:11.560924 2024] [wsgi:error] [pid 23811] [remote 65.49.1.36:48157]     raise NotImplementedError, 'emit must be implemented '\\
[Fri Nov 01 23:59:11.560939 2024] [wsgi:error] [pid 23811] [remote 65.49.1.36:48157]                              ^
[Fri Nov 01 23:59:11.560947 2024] [wsgi:error] [pid 23811] [remote 65.49.1.36:48157] SyntaxError: invalid syntax
[Sat Nov 02 00:00:13.619293 2024] [wsgi:error] [pid 23811] [remote 65.49.1.29:64873] mod_wsgi (pid=23811): Failed to exec Python script file '/var/www/bdatalab/bdatalab.wsgi'.
[Sat Nov 02 00:00:13.619394 2024] [wsgi:error] [pid 23811] [remote 65.49.1.29:64873] mod_wsgi (pid=23811): Exception occurred processing WSGI script '/var/www/bdatalab/bdatalab.wsgi'.
[Sat Nov 02 00:00:13.619644 2024] [wsgi:error] [pid 23811] [remote 65.49.1.29:64873] Traceback (most recent call last):
[Sat Nov 02 00:00:13.619898 2024] [wsgi:error] [pid 23811] [remote 65.49.1.29:64873]   File "/var/www/bdatalab/bdatalab.wsgi", line 8, in <module>
[Sat Nov 02 00:00:13.619910 2024] [wsgi:error] [pid 23811] [remote 65.49.1.29:64873]     from app import create_app
[Sat Nov 02 00:00:13.619919 2024] [wsgi:error] [pid 23811] [remote 65.49.1.29:64873]   File "/var/www/bdatalab/app/__init__.py", line 2, in <module>
[Sat Nov 02 00:00:13.619924 2024] [wsgi:error] [pid 23811] [remote 65.49.1.29:64873]     from flask import Flask
[Sat Nov 02 00:00:13.619933 2024] [wsgi:error] [pid 23811] [remote 65.49.1.29:64873]   File "/var/www/bdatalab/venv/lib/python3.12/site-packages/flask/__init__.py", line 5, in <module>
[Sat Nov 02 00:00:13.619937 2024] [wsgi:error] [pid 23811] [remote 65.49.1.29:64873]     from . import json as json
[Sat Nov 02 00:00:13.619952 2024] [wsgi:error] [pid 23811] [remote 65.49.1.29:64873]   File "/var/www/bdatalab/venv/lib/python3.12/site-packages/flask/json/__init__.py", line 6, in <module>
[Sat Nov 02 00:00:13.619957 2024] [wsgi:error] [pid 23811] [remote 65.49.1.29:64873]     from ..globals import current_app
[Sat Nov 02 00:00:13.619966 2024] [wsgi:error] [pid 23811] [remote 65.49.1.29:64873]   File "/var/www/bdatalab/venv/lib/python3.12/site-packages/flask/globals.py", line 6, in <module>
[Sat Nov 02 00:00:13.619970 2024] [wsgi:error] [pid 23811] [remote 65.49.1.29:64873]     from werkzeug.local import LocalProxy
[Sat Nov 02 00:00:13.619992 2024] [wsgi:error] [pid 23811] [remote 65.49.1.29:64873]   File "/var/www/bdatalab/venv/lib/python3.12/site-packages/werkzeug/__init__.py", line 1, in <module>
[Sat Nov 02 00:00:13.619995 2024] [wsgi:error] [pid 23811] [remote 65.49.1.29:64873]     from .serving import run_simple as run_simple
[Sat Nov 02 00:00:13.620002 2024] [wsgi:error] [pid 23811] [remote 65.49.1.29:64873]   File "/var/www/bdatalab/venv/lib/python3.12/site-packages/werkzeug/serving.py", line 33, in <module>
[Sat Nov 02 00:00:13.620005 2024] [wsgi:error] [pid 23811] [remote 65.49.1.29:64873]     from ._internal import _log
[Sat Nov 02 00:00:13.620012 2024] [wsgi:error] [pid 23811] [remote 65.49.1.29:64873]   File "/var/www/bdatalab/venv/lib/python3.12/site-packages/werkzeug/_internal.py", line 3, in <module>
[Sat Nov 02 00:00:13.620015 2024] [wsgi:error] [pid 23811] [remote 65.49.1.29:64873]     import logging
[Sat Nov 02 00:00:13.620033 2024] [wsgi:error] [pid 23811] [remote 65.49.1.29:64873]   File "/var/www/bdatalab/venv/lib/python3.12/site-packages/logging/__init__.py", line 618
[Sat Nov 02 00:00:13.620043 2024] [wsgi:error] [pid 23811] [remote 65.49.1.29:64873]     raise NotImplementedError, 'emit must be implemented '\\
[Sat Nov 02 00:00:13.620057 2024] [wsgi:error] [pid 23811] [remote 65.49.1.29:64873]                              ^
[Sat Nov 02 00:00:13.620066 2024] [wsgi:error] [pid 23811] [remote 65.49.1.29:64873] SyntaxError: invalid syntax
[Sat Nov 02 00:03:20.371481 2024] [wsgi:error] [pid 23811] [remote 65.49.1.29:63317] mod_wsgi (pid=23811): Failed to exec Python script file '/var/www/bdatalab/bdatalab.wsgi'.
[Sat Nov 02 00:03:20.371572 2024] [wsgi:error] [pid 23811] [remote 65.49.1.29:63317] mod_wsgi (pid=23811): Exception occurred processing WSGI script '/var/www/bdatalab/bdatalab.wsgi'.
[Sat Nov 02 00:03:20.371865 2024] [wsgi:error] [pid 23811] [remote 65.49.1.29:63317] Traceback (most recent call last):
[Sat Nov 02 00:03:20.372198 2024] [wsgi:error] [pid 23811] [remote 65.49.1.29:63317]   File "/var/www/bdatalab/bdatalab.wsgi", line 8, in <module>
[Sat Nov 02 00:03:20.372209 2024] [wsgi:error] [pid 23811] [remote 65.49.1.29:63317]     from app import create_app
[Sat Nov 02 00:03:20.372222 2024] [wsgi:error] [pid 23811] [remote 65.49.1.29:63317]   File "/var/www/bdatalab/app/__init__.py", line 2, in <module>
[Sat Nov 02 00:03:20.372228 2024] [wsgi:error] [pid 23811] [remote 65.49.1.29:63317]     from flask import Flask
[Sat Nov 02 00:03:20.372251 2024] [wsgi:error] [pid 23811] [remote 65.49.1.29:63317]   File "/var/www/bdatalab/venv/lib/python3.12/site-packages/flask/__init__.py", line 5, in <module>
[Sat Nov 02 00:03:20.372258 2024] [wsgi:error] [pid 23811] [remote 65.49.1.29:63317]     from . import json as json
[Sat Nov 02 00:03:20.372280 2024] [wsgi:error] [pid 23811] [remote 65.49.1.29:63317]   File "/var/www/bdatalab/venv/lib/python3.12/site-packages/flask/json/__init__.py", line 6, in <module>
[Sat Nov 02 00:03:20.372289 2024] [wsgi:error] [pid 23811] [remote 65.49.1.29:63317]     from ..globals import current_app
[Sat Nov 02 00:03:20.372309 2024] [wsgi:error] [pid 23811] [remote 65.49.1.29:63317]   File "/var/www/bdatalab/venv/lib/python3.12/site-packages/flask/globals.py", line 6, in <module>
[Sat Nov 02 00:03:20.372318 2024] [wsgi:error] [pid 23811] [remote 65.49.1.29:63317]     from werkzeug.local import LocalProxy
[Sat Nov 02 00:03:20.372328 2024] [wsgi:error] [pid 23811] [remote 65.49.1.29:63317]   File "/var/www/bdatalab/venv/lib/python3.12/site-packages/werkzeug/__init__.py", line 1, in <module>
[Sat Nov 02 00:03:20.372333 2024] [wsgi:error] [pid 23811] [remote 65.49.1.29:63317]     from .serving import run_simple as run_simple
[Sat Nov 02 00:03:20.372341 2024] [wsgi:error] [pid 23811] [remote 65.49.1.29:63317]   File "/var/www/bdatalab/venv/lib/python3.12/site-packages/werkzeug/serving.py", line 33, in <module>
[Sat Nov 02 00:03:20.372346 2024] [wsgi:error] [pid 23811] [remote 65.49.1.29:63317]     from ._internal import _log
[Sat Nov 02 00:03:20.372370 2024] [wsgi:error] [pid 23811] [remote 65.49.1.29:63317]   File "/var/www/bdatalab/venv/lib/python3.12/site-packages/werkzeug/_internal.py", line 3, in <module>
[Sat Nov 02 00:03:20.372374 2024] [wsgi:error] [pid 23811] [remote 65.49.1.29:63317]     import logging
[Sat Nov 02 00:03:20.372392 2024] [wsgi:error] [pid 23811] [remote 65.49.1.29:63317]   File "/var/www/bdatalab/venv/lib/python3.12/site-packages/logging/__init__.py", line 618
[Sat Nov 02 00:03:20.372403 2024] [wsgi:error] [pid 23811] [remote 65.49.1.29:63317]     raise NotImplementedError, 'emit must be implemented '\\
[Sat Nov 02 00:03:20.372422 2024] [wsgi:error] [pid 23811] [remote 65.49.1.29:63317]                              ^
[Sat Nov 02 00:03:20.372441 2024] [wsgi:error] [pid 23811] [remote 65.49.1.29:63317] SyntaxError: invalid syntax
[Sat Nov 02 00:04:42.240182 2024] [wsgi:error] [pid 23811] [remote 65.49.1.36:9911] mod_wsgi (pid=23811): Failed to exec Python script file '/var/www/bdatalab/bdatalab.wsgi'.
[Sat Nov 02 00:04:42.240246 2024] [wsgi:error] [pid 23811] [remote 65.49.1.36:9911] mod_wsgi (pid=23811): Exception occurred processing WSGI script '/var/www/bdatalab/bdatalab.wsgi'.
[Sat Nov 02 00:04:42.240447 2024] [wsgi:error] [pid 23811] [remote 65.49.1.36:9911] Traceback (most recent call last):
[Sat Nov 02 00:04:42.240727 2024] [wsgi:error] [pid 23811] [remote 65.49.1.36:9911]   File "/var/www/bdatalab/bdatalab.wsgi", line 8, in <module>
[Sat Nov 02 00:04:42.240739 2024] [wsgi:error] [pid 23811] [remote 65.49.1.36:9911]     from app import create_app
[Sat Nov 02 00:04:42.240750 2024] [wsgi:error] [pid 23811] [remote 65.49.1.36:9911]   File "/var/www/bdatalab/app/__init__.py", line 2, in <module>
[Sat Nov 02 00:04:42.240755 2024] [wsgi:error] [pid 23811] [remote 65.49.1.36:9911]     from flask import Flask
[Sat Nov 02 00:04:42.240764 2024] [wsgi:error] [pid 23811] [remote 65.49.1.36:9911]   File "/var/www/bdatalab/venv/lib/python3.12/site-packages/flask/__init__.py", line 5, in <module>
[Sat Nov 02 00:04:42.240768 2024] [wsgi:error] [pid 23811] [remote 65.49.1.36:9911]     from . import json as json
[Sat Nov 02 00:04:42.240777 2024] [wsgi:error] [pid 23811] [remote 65.49.1.36:9911]   File "/var/www/bdatalab/venv/lib/python3.12/site-packages/flask/json/__init__.py", line 6, in <module>
[Sat Nov 02 00:04:42.240782 2024] [wsgi:error] [pid 23811] [remote 65.49.1.36:9911]     from ..globals import current_app
[Sat Nov 02 00:04:42.240790 2024] [wsgi:error] [pid 23811] [remote 65.49.1.36:9911]   File "/var/www/bdatalab/venv/lib/python3.12/site-packages/flask/globals.py", line 6, in <module>
[Sat Nov 02 00:04:42.240795 2024] [wsgi:error] [pid 23811] [remote 65.49.1.36:9911]     from werkzeug.local import LocalProxy
[Sat Nov 02 00:04:42.240831 2024] [wsgi:error] [pid 23811] [remote 65.49.1.36:9911]   File "/var/www/bdatalab/venv/lib/python3.12/site-packages/werkzeug/__init__.py", line 1, in <module>
[Sat Nov 02 00:04:42.240845 2024] [wsgi:error] [pid 23811] [remote 65.49.1.36:9911]     from .serving import run_simple as run_simple
[Sat Nov 02 00:04:42.240866 2024] [wsgi:error] [pid 23811] [remote 65.49.1.36:9911]   File "/var/www/bdatalab/venv/lib/python3.12/site-packages/werkzeug/serving.py", line 33, in <module>
[Sat Nov 02 00:04:42.240871 2024] [wsgi:error] [pid 23811] [remote 65.49.1.36:9911]     from ._internal import _log
[Sat Nov 02 00:04:42.240881 2024] [wsgi:error] [pid 23811] [remote 65.49.1.36:9911]   File "/var/www/bdatalab/venv/lib/python3.12/site-packages/werkzeug/_internal.py", line 3, in <module>
[Sat Nov 02 00:04:42.240885 2024] [wsgi:error] [pid 23811] [remote 65.49.1.36:9911]     import logging
[Sat Nov 02 00:04:42.240903 2024] [wsgi:error] [pid 23811] [remote 65.49.1.36:9911]   File "/var/www/bdatalab/venv/lib/python3.12/site-packages/logging/__init__.py", line 618
[Sat Nov 02 00:04:42.240914 2024] [wsgi:error] [pid 23811] [remote 65.49.1.36:9911]     raise NotImplementedError, 'emit must be implemented '\\
[Sat Nov 02 00:04:42.240931 2024] [wsgi:error] [pid 23811] [remote 65.49.1.36:9911]                              ^
[Sat Nov 02 00:04:42.240954 2024] [wsgi:error] [pid 23811] [remote 65.49.1.36:9911] SyntaxError: invalid syntax
[Sat Nov 02 00:10:50.019332 2024] [wsgi:error] [pid 24075] [remote 177.93.3.83:33862] mod_wsgi (pid=24075): Failed to exec Python script file '/var/www/bdatalab/bdatalab.wsgi'.
[Sat Nov 02 00:10:50.019456 2024] [wsgi:error] [pid 24075] [remote 177.93.3.83:33862] mod_wsgi (pid=24075): Exception occurred processing WSGI script '/var/www/bdatalab/bdatalab.wsgi'.
[Sat Nov 02 00:10:50.025636 2024] [wsgi:error] [pid 24075] [remote 177.93.3.83:33862] Traceback (most recent call last):
[Sat Nov 02 00:10:50.028151 2024] [wsgi:error] [pid 24075] [remote 177.93.3.83:33862]   File "/var/www/bdatalab/bdatalab.wsgi", line 8, in <module>
[Sat Nov 02 00:10:50.028167 2024] [wsgi:error] [pid 24075] [remote 177.93.3.83:33862]     from app import create_app
[Sat Nov 02 00:10:50.028188 2024] [wsgi:error] [pid 24075] [remote 177.93.3.83:33862]   File "/var/www/bdatalab/app/__init__.py", line 2, in <module>
[Sat Nov 02 00:10:50.028198 2024] [wsgi:error] [pid 24075] [remote 177.93.3.83:33862]     from flask import Flask
[Sat Nov 02 00:10:50.028209 2024] [wsgi:error] [pid 24075] [remote 177.93.3.83:33862]   File "/var/www/bdatalab/venv/lib/python3.12/site-packages/flask/__init__.py", line 5, in <module>
[Sat Nov 02 00:10:50.028214 2024] [wsgi:error] [pid 24075] [remote 177.93.3.83:33862]     from . import json as json
[Sat Nov 02 00:10:50.028223 2024] [wsgi:error] [pid 24075] [remote 177.93.3.83:33862]   File "/var/www/bdatalab/venv/lib/python3.12/site-packages/flask/json/__init__.py", line 6, in <module>
[Sat Nov 02 00:10:50.028227 2024] [wsgi:error] [pid 24075] [remote 177.93.3.83:33862]     from ..globals import current_app
[Sat Nov 02 00:10:50.028236 2024] [wsgi:error] [pid 24075] [remote 177.93.3.83:33862]   File "/var/www/bdatalab/venv/lib/python3.12/site-packages/flask/globals.py", line 6, in <module>
[Sat Nov 02 00:10:50.028241 2024] [wsgi:error] [pid 24075] [remote 177.93.3.83:33862]     from werkzeug.local import LocalProxy
[Sat Nov 02 00:10:50.028266 2024] [wsgi:error] [pid 24075] [remote 177.93.3.83:33862]   File "/var/www/bdatalab/venv/lib/python3.12/site-packages/werkzeug/__init__.py", line 1, in <module>
[Sat Nov 02 00:10:50.028271 2024] [wsgi:error] [pid 24075] [remote 177.93.3.83:33862]     from .serving import run_simple as run_simple
[Sat Nov 02 00:10:50.028280 2024] [wsgi:error] [pid 24075] [remote 177.93.3.83:33862]   File "/var/www/bdatalab/venv/lib/python3.12/site-packages/werkzeug/serving.py", line 33, in <module>
[Sat Nov 02 00:10:50.028285 2024] [wsgi:error] [pid 24075] [remote 177.93.3.83:33862]     from ._internal import _log
[Sat Nov 02 00:10:50.028293 2024] [wsgi:error] [pid 24075] [remote 177.93.3.83:33862]   File "/var/www/bdatalab/venv/lib/python3.12/site-packages/werkzeug/_internal.py", line 3, in <module>
[Sat Nov 02 00:10:50.028298 2024] [wsgi:error] [pid 24075] [remote 177.93.3.83:33862]     import logging
[Sat Nov 02 00:10:50.028317 2024] [wsgi:error] [pid 24075] [remote 177.93.3.83:33862]   File "/var/www/bdatalab/venv/lib/python3.12/site-packages/logging/__init__.py", line 618
[Sat Nov 02 00:10:50.028330 2024] [wsgi:error] [pid 24075] [remote 177.93.3.83:33862]     raise NotImplementedError, 'emit must be implemented '\\
[Sat Nov 02 00:10:50.028348 2024] [wsgi:error] [pid 24075] [remote 177.93.3.83:33862]                              ^
[Sat Nov 02 00:10:50.028357 2024] [wsgi:error] [pid 24075] [remote 177.93.3.83:33862] SyntaxError: invalid syntax
[Sat Nov 02 00:12:50.555366 2024] [wsgi:error] [pid 24135] [remote 177.93.3.83:39944] mod_wsgi (pid=24135): Failed to exec Python script file '/var/www/bdatalab/bdatalab.wsgi'.
[Sat Nov 02 00:12:50.555470 2024] [wsgi:error] [pid 24135] [remote 177.93.3.83:39944] mod_wsgi (pid=24135): Exception occurred processing WSGI script '/var/www/bdatalab/bdatalab.wsgi'.
[Sat Nov 02 00:12:50.566401 2024] [wsgi:error] [pid 24135] [remote 177.93.3.83:39944] Traceback (most recent call last):
[Sat Nov 02 00:12:50.568931 2024] [wsgi:error] [pid 24135] [remote 177.93.3.83:39944]   File "/var/www/bdatalab/bdatalab.wsgi", line 8, in <module>
[Sat Nov 02 00:12:50.568960 2024] [wsgi:error] [pid 24135] [remote 177.93.3.83:39944]     from app import create_app
[Sat Nov 02 00:12:50.568970 2024] [wsgi:error] [pid 24135] [remote 177.93.3.83:39944]   File "/var/www/bdatalab/app/__init__.py", line 2, in <module>
[Sat Nov 02 00:12:50.568973 2024] [wsgi:error] [pid 24135] [remote 177.93.3.83:39944]     from flask import Flask
[Sat Nov 02 00:12:50.568981 2024] [wsgi:error] [pid 24135] [remote 177.93.3.83:39944]   File "/var/www/bdatalab/venv/lib/python3.12/site-packages/flask/__init__.py", line 5, in <module>
[Sat Nov 02 00:12:50.568984 2024] [wsgi:error] [pid 24135] [remote 177.93.3.83:39944]     from . import json as json
[Sat Nov 02 00:12:50.568991 2024] [wsgi:error] [pid 24135] [remote 177.93.3.83:39944]   File "/var/www/bdatalab/venv/lib/python3.12/site-packages/flask/json/__init__.py", line 6, in <module>
[Sat Nov 02 00:12:50.568994 2024] [wsgi:error] [pid 24135] [remote 177.93.3.83:39944]     from ..globals import current_app
[Sat Nov 02 00:12:50.569001 2024] [wsgi:error] [pid 24135] [remote 177.93.3.83:39944]   File "/var/www/bdatalab/venv/lib/python3.12/site-packages/flask/globals.py", line 6, in <module>
[Sat Nov 02 00:12:50.569004 2024] [wsgi:error] [pid 24135] [remote 177.93.3.83:39944]     from werkzeug.local import LocalProxy
[Sat Nov 02 00:12:50.569011 2024] [wsgi:error] [pid 24135] [remote 177.93.3.83:39944]   File "/var/www/bdatalab/venv/lib/python3.12/site-packages/werkzeug/__init__.py", line 1, in <module>
[Sat Nov 02 00:12:50.569014 2024] [wsgi:error] [pid 24135] [remote 177.93.3.83:39944]     from .serving import run_simple as run_simple
[Sat Nov 02 00:12:50.569021 2024] [wsgi:error] [pid 24135] [remote 177.93.3.83:39944]   File "/var/www/bdatalab/venv/lib/python3.12/site-packages/werkzeug/serving.py", line 33, in <module>
[Sat Nov 02 00:12:50.569024 2024] [wsgi:error] [pid 24135] [remote 177.93.3.83:39944]     from ._internal import _log
[Sat Nov 02 00:12:50.569030 2024] [wsgi:error] [pid 24135] [remote 177.93.3.83:39944]   File "/var/www/bdatalab/venv/lib/python3.12/site-packages/werkzeug/_internal.py", line 3, in <module>
[Sat Nov 02 00:12:50.569034 2024] [wsgi:error] [pid 24135] [remote 177.93.3.83:39944]     import logging
[Sat Nov 02 00:12:50.569048 2024] [wsgi:error] [pid 24135] [remote 177.93.3.83:39944]   File "/var/www/bdatalab/venv/lib/python3.12/site-packages/logging/__init__.py", line 618
[Sat Nov 02 00:12:50.569058 2024] [wsgi:error] [pid 24135] [remote 177.93.3.83:39944]     raise NotImplementedError, 'emit must be implemented '\\
[Sat Nov 02 00:12:50.569073 2024] [wsgi:error] [pid 24135] [remote 177.93.3.83:39944]                              ^
[Sat Nov 02 00:12:50.569081 2024] [wsgi:error] [pid 24135] [remote 177.93.3.83:39944] SyntaxError: invalid syntax
[Sat Nov 02 00:16:07.865566 2024] [wsgi:error] [pid 24190] [remote 177.93.3.83:51204] mod_wsgi (pid=24190): Failed to exec Python script file '/var/www/bdatalab/bdatalab.wsgi'.
[Sat Nov 02 00:16:07.865643 2024] [wsgi:error] [pid 24190] [remote 177.93.3.83:51204] mod_wsgi (pid=24190): Exception occurred processing WSGI script '/var/www/bdatalab/bdatalab.wsgi'.
[Sat Nov 02 00:16:07.870755 2024] [wsgi:error] [pid 24190] [remote 177.93.3.83:51204] Traceback (most recent call last):
[Sat Nov 02 00:16:07.873123 2024] [wsgi:error] [pid 24190] [remote 177.93.3.83:51204]   File "/var/www/bdatalab/bdatalab.wsgi", line 8, in <module>
[Sat Nov 02 00:16:07.873138 2024] [wsgi:error] [pid 24190] [remote 177.93.3.83:51204]     from app import create_app
[Sat Nov 02 00:16:07.873151 2024] [wsgi:error] [pid 24190] [remote 177.93.3.83:51204]   File "/var/www/bdatalab/app/__init__.py", line 2, in <module>
[Sat Nov 02 00:16:07.873156 2024] [wsgi:error] [pid 24190] [remote 177.93.3.83:51204]     from flask import Flask
[Sat Nov 02 00:16:07.873176 2024] [wsgi:error] [pid 24190] [remote 177.93.3.83:51204]   File "/var/www/bdatalab/venv/lib/python3.12/site-packages/flask/__init__.py", line 5, in <module>
[Sat Nov 02 00:16:07.873187 2024] [wsgi:error] [pid 24190] [remote 177.93.3.83:51204]     from . import json as json
[Sat Nov 02 00:16:07.873224 2024] [wsgi:error] [pid 24190] [remote 177.93.3.83:51204]   File "/var/www/bdatalab/venv/lib/python3.12/site-packages/flask/json/__init__.py", line 6, in <module>
[Sat Nov 02 00:16:07.873231 2024] [wsgi:error] [pid 24190] [remote 177.93.3.83:51204]     from ..globals import current_app
[Sat Nov 02 00:16:07.873240 2024] [wsgi:error] [pid 24190] [remote 177.93.3.83:51204]   File "/var/www/bdatalab/venv/lib/python3.12/site-packages/flask/globals.py", line 6, in <module>
[Sat Nov 02 00:16:07.873244 2024] [wsgi:error] [pid 24190] [remote 177.93.3.83:51204]     from werkzeug.local import LocalProxy
[Sat Nov 02 00:16:07.873250 2024] [wsgi:error] [pid 24190] [remote 177.93.3.83:51204]   File "/var/www/bdatalab/venv/lib/python3.12/site-packages/werkzeug/__init__.py", line 1, in <module>
[Sat Nov 02 00:16:07.873254 2024] [wsgi:error] [pid 24190] [remote 177.93.3.83:51204]     from .serving import run_simple as run_simple
[Sat Nov 02 00:16:07.873261 2024] [wsgi:error] [pid 24190] [remote 177.93.3.83:51204]   File "/var/www/bdatalab/venv/lib/python3.12/site-packages/werkzeug/serving.py", line 33, in <module>
[Sat Nov 02 00:16:07.873264 2024] [wsgi:error] [pid 24190] [remote 177.93.3.83:51204]     from ._internal import _log
[Sat Nov 02 00:16:07.873271 2024] [wsgi:error] [pid 24190] [remote 177.93.3.83:51204]   File "/var/www/bdatalab/venv/lib/python3.12/site-packages/werkzeug/_internal.py", line 3, in <module>
[Sat Nov 02 00:16:07.873274 2024] [wsgi:error] [pid 24190] [remote 177.93.3.83:51204]     import logging
[Sat Nov 02 00:16:07.873290 2024] [wsgi:error] [pid 24190] [remote 177.93.3.83:51204]   File "/var/www/bdatalab/venv/lib/python3.12/site-packages/logging/__init__.py", line 618
[Sat Nov 02 00:16:07.873300 2024] [wsgi:error] [pid 24190] [remote 177.93.3.83:51204]     raise NotImplementedError, 'emit must be implemented '\\
[Sat Nov 02 00:16:07.873316 2024] [wsgi:error] [pid 24190] [remote 177.93.3.83:51204]                              ^
[Sat Nov 02 00:16:07.873324 2024] [wsgi:error] [pid 24190] [remote 177.93.3.83:51204] SyntaxError: invalid syntax
[Sat Nov 02 00:16:14.372479 2024] [wsgi:error] [pid 24190] [remote 177.93.3.83:51218] mod_wsgi (pid=24190): Failed to exec Python script file '/var/www/bdatalab/bdatalab.wsgi'.
[Sat Nov 02 00:16:14.372579 2024] [wsgi:error] [pid 24190] [remote 177.93.3.83:51218] mod_wsgi (pid=24190): Exception occurred processing WSGI script '/var/www/bdatalab/bdatalab.wsgi'.
[Sat Nov 02 00:16:14.373522 2024] [wsgi:error] [pid 24190] [remote 177.93.3.83:51218] Traceback (most recent call last):
[Sat Nov 02 00:16:14.373749 2024] [wsgi:error] [pid 24190] [remote 177.93.3.83:51218]   File "/var/www/bdatalab/bdatalab.wsgi", line 8, in <module>
[Sat Nov 02 00:16:14.373757 2024] [wsgi:error] [pid 24190] [remote 177.93.3.83:51218]     from app import create_app
[Sat Nov 02 00:16:14.373766 2024] [wsgi:error] [pid 24190] [remote 177.93.3.83:51218]   File "/var/www/bdatalab/app/__init__.py", line 2, in <module>
[Sat Nov 02 00:16:14.373771 2024] [wsgi:error] [pid 24190] [remote 177.93.3.83:51218]     from flask import Flask
[Sat Nov 02 00:16:14.373780 2024] [wsgi:error] [pid 24190] [remote 177.93.3.83:51218]   File "/var/www/bdatalab/venv/lib/python3.12/site-packages/flask/__init__.py", line 5, in <module>
[Sat Nov 02 00:16:14.373784 2024] [wsgi:error] [pid 24190] [remote 177.93.3.83:51218]     from . import json as json
[Sat Nov 02 00:16:14.373793 2024] [wsgi:error] [pid 24190] [remote 177.93.3.83:51218]   File "/var/www/bdatalab/venv/lib/python3.12/site-packages/flask/json/__init__.py", line 6, in <module>
[Sat Nov 02 00:16:14.373798 2024] [wsgi:error] [pid 24190] [remote 177.93.3.83:51218]     from ..globals import current_app
[Sat Nov 02 00:16:14.373842 2024] [wsgi:error] [pid 24190] [remote 177.93.3.83:51218]   File "/var/www/bdatalab/venv/lib/python3.12/site-packages/flask/globals.py", line 6, in <module>
[Sat Nov 02 00:16:14.373855 2024] [wsgi:error] [pid 24190] [remote 177.93.3.83:51218]     from werkzeug.local import LocalProxy
[Sat Nov 02 00:16:14.373906 2024] [wsgi:error] [pid 24190] [remote 177.93.3.83:51218]   File "/var/www/bdatalab/venv/lib/python3.12/site-packages/werkzeug/__init__.py", line 1, in <module>
[Sat Nov 02 00:16:14.373911 2024] [wsgi:error] [pid 24190] [remote 177.93.3.83:51218]     from .serving import run_simple as run_simple
[Sat Nov 02 00:16:14.373918 2024] [wsgi:error] [pid 24190] [remote 177.93.3.83:51218]   File "/var/www/bdatalab/venv/lib/python3.12/site-packages/werkzeug/serving.py", line 33, in <module>
[Sat Nov 02 00:16:14.373922 2024] [wsgi:error] [pid 24190] [remote 177.93.3.83:51218]     from ._internal import _log
[Sat Nov 02 00:16:14.373929 2024] [wsgi:error] [pid 24190] [remote 177.93.3.83:51218]   File "/var/www/bdatalab/venv/lib/python3.12/site-packages/werkzeug/_internal.py", line 3, in <module>
[Sat Nov 02 00:16:14.373932 2024] [wsgi:error] [pid 24190] [remote 177.93.3.83:51218]     import logging
[Sat Nov 02 00:16:14.373951 2024] [wsgi:error] [pid 24190] [remote 177.93.3.83:51218]   File "/var/www/bdatalab/venv/lib/python3.12/site-packages/logging/__init__.py", line 618
[Sat Nov 02 00:16:14.373962 2024] [wsgi:error] [pid 24190] [remote 177.93.3.83:51218]     raise NotImplementedError, 'emit must be implemented '\\
[Sat Nov 02 00:16:14.373979 2024] [wsgi:error] [pid 24190] [remote 177.93.3.83:51218]                              ^
[Sat Nov 02 00:16:14.373987 2024] [wsgi:error] [pid 24190] [remote 177.93.3.83:51218] SyntaxError: invalid syntax
[Sat Nov 02 00:16:15.402713 2024] [wsgi:error] [pid 24190] [remote 177.93.3.83:49244] mod_wsgi (pid=24190): Failed to exec Python script file '/var/www/bdatalab/bdatalab.wsgi'.
[Sat Nov 02 00:16:15.402822 2024] [wsgi:error] [pid 24190] [remote 177.93.3.83:49244] mod_wsgi (pid=24190): Exception occurred processing WSGI script '/var/www/bdatalab/bdatalab.wsgi'.
[Sat Nov 02 00:16:15.403059 2024] [wsgi:error] [pid 24190] [remote 177.93.3.83:49244] Traceback (most recent call last):
[Sat Nov 02 00:16:15.403273 2024] [wsgi:error] [pid 24190] [remote 177.93.3.83:49244]   File "/var/www/bdatalab/bdatalab.wsgi", line 8, in <module>
[Sat Nov 02 00:16:15.403280 2024] [wsgi:error] [pid 24190] [remote 177.93.3.83:49244]     from app import create_app
[Sat Nov 02 00:16:15.403288 2024] [wsgi:error] [pid 24190] [remote 177.93.3.83:49244]   File "/var/www/bdatalab/app/__init__.py", line 2, in <module>
[Sat Nov 02 00:16:15.403291 2024] [wsgi:error] [pid 24190] [remote 177.93.3.83:49244]     from flask import Flask
[Sat Nov 02 00:16:15.403298 2024] [wsgi:error] [pid 24190] [remote 177.93.3.83:49244]   File "/var/www/bdatalab/venv/lib/python3.12/site-packages/flask/__init__.py", line 5, in <module>
[Sat Nov 02 00:16:15.403301 2024] [wsgi:error] [pid 24190] [remote 177.93.3.83:49244]     from . import json as json
[Sat Nov 02 00:16:15.403309 2024] [wsgi:error] [pid 24190] [remote 177.93.3.83:49244]   File "/var/www/bdatalab/venv/lib/python3.12/site-packages/flask/json/__init__.py", line 6, in <module>
[Sat Nov 02 00:16:15.403312 2024] [wsgi:error] [pid 24190] [remote 177.93.3.83:49244]     from ..globals import current_app
[Sat Nov 02 00:16:15.403321 2024] [wsgi:error] [pid 24190] [remote 177.93.3.83:49244]   File "/var/www/bdatalab/venv/lib/python3.12/site-packages/flask/globals.py", line 6, in <module>
[Sat Nov 02 00:16:15.403328 2024] [wsgi:error] [pid 24190] [remote 177.93.3.83:49244]     from werkzeug.local import LocalProxy
[Sat Nov 02 00:16:15.403342 2024] [wsgi:error] [pid 24190] [remote 177.93.3.83:49244]   File "/var/www/bdatalab/venv/lib/python3.12/site-packages/werkzeug/__init__.py", line 1, in <module>
[Sat Nov 02 00:16:15.403346 2024] [wsgi:error] [pid 24190] [remote 177.93.3.83:49244]     from .serving import run_simple as run_simple
[Sat Nov 02 00:16:15.403354 2024] [wsgi:error] [pid 24190] [remote 177.93.3.83:49244]   File "/var/www/bdatalab/venv/lib/python3.12/site-packages/werkzeug/serving.py", line 33, in <module>
[Sat Nov 02 00:16:15.403358 2024] [wsgi:error] [pid 24190] [remote 177.93.3.83:49244]     from ._internal import _log
[Sat Nov 02 00:16:15.403384 2024] [wsgi:error] [pid 24190] [remote 177.93.3.83:49244]   File "/var/www/bdatalab/venv/lib/python3.12/site-packages/werkzeug/_internal.py", line 3, in <module>
[Sat Nov 02 00:16:15.403388 2024] [wsgi:error] [pid 24190] [remote 177.93.3.83:49244]     import logging
[Sat Nov 02 00:16:15.403411 2024] [wsgi:error] [pid 24190] [remote 177.93.3.83:49244]   File "/var/www/bdatalab/venv/lib/python3.12/site-packages/logging/__init__.py", line 618
[Sat Nov 02 00:16:15.403428 2024] [wsgi:error] [pid 24190] [remote 177.93.3.83:49244]     raise NotImplementedError, 'emit must be implemented '\\
[Sat Nov 02 00:16:15.403470 2024] [wsgi:error] [pid 24190] [remote 177.93.3.83:49244]                              ^
[Sat Nov 02 00:16:15.403480 2024] [wsgi:error] [pid 24190] [remote 177.93.3.83:49244] SyntaxError: invalid syntax
[Sat Nov 02 00:20:53.820796 2024] [wsgi:error] [pid 24190] [remote 51.79.160.196:51806] mod_wsgi (pid=24190): Failed to exec Python script file '/var/www/bdatalab/bdatalab.wsgi'.
[Sat Nov 02 00:20:53.823056 2024] [wsgi:error] [pid 24190] [remote 51.79.160.196:51806] mod_wsgi (pid=24190): Exception occurred processing WSGI script '/var/www/bdatalab/bdatalab.wsgi'.
[Sat Nov 02 00:20:53.823674 2024] [wsgi:error] [pid 24190] [remote 51.79.160.196:51806] Traceback (most recent call last):
[Sat Nov 02 00:20:53.823991 2024] [wsgi:error] [pid 24190] [remote 51.79.160.196:51806]   File "/var/www/bdatalab/bdatalab.wsgi", line 8, in <module>
[Sat Nov 02 00:20:53.824004 2024] [wsgi:error] [pid 24190] [remote 51.79.160.196:51806]     from app import create_app
[Sat Nov 02 00:20:53.824015 2024] [wsgi:error] [pid 24190] [remote 51.79.160.196:51806]   File "/var/www/bdatalab/app/__init__.py", line 2, in <module>
[Sat Nov 02 00:20:53.824020 2024] [wsgi:error] [pid 24190] [remote 51.79.160.196:51806]     from flask import Flask
[Sat Nov 02 00:20:53.824029 2024] [wsgi:error] [pid 24190] [remote 51.79.160.196:51806]   File "/var/www/bdatalab/venv/lib/python3.12/site-packages/flask/__init__.py", line 5, in <module>
[Sat Nov 02 00:20:53.824034 2024] [wsgi:error] [pid 24190] [remote 51.79.160.196:51806]     from . import json as json
[Sat Nov 02 00:20:53.824043 2024] [wsgi:error] [pid 24190] [remote 51.79.160.196:51806]   File "/var/www/bdatalab/venv/lib/python3.12/site-packages/flask/json/__init__.py", line 6, in <module>
[Sat Nov 02 00:20:53.824048 2024] [wsgi:error] [pid 24190] [remote 51.79.160.196:51806]     from ..globals import current_app
[Sat Nov 02 00:20:53.824057 2024] [wsgi:error] [pid 24190] [remote 51.79.160.196:51806]   File "/var/www/bdatalab/venv/lib/python3.12/site-packages/flask/globals.py", line 6, in <module>
[Sat Nov 02 00:20:53.824061 2024] [wsgi:error] [pid 24190] [remote 51.79.160.196:51806]     from werkzeug.local import LocalProxy
[Sat Nov 02 00:20:53.824070 2024] [wsgi:error] [pid 24190] [remote 51.79.160.196:51806]   File "/var/www/bdatalab/venv/lib/python3.12/site-packages/werkzeug/__init__.py", line 1, in <module>
[Sat Nov 02 00:20:53.824075 2024] [wsgi:error] [pid 24190] [remote 51.79.160.196:51806]     from .serving import run_simple as run_simple
[Sat Nov 02 00:20:53.824084 2024] [wsgi:error] [pid 24190] [remote 51.79.160.196:51806]   File "/var/www/bdatalab/venv/lib/python3.12/site-packages/werkzeug/serving.py", line 33, in <module>
[Sat Nov 02 00:20:53.824088 2024] [wsgi:error] [pid 24190] [remote 51.79.160.196:51806]     from ._internal import _log
[Sat Nov 02 00:20:53.824097 2024] [wsgi:error] [pid 24190] [remote 51.79.160.196:51806]   File "/var/www/bdatalab/venv/lib/python3.12/site-packages/werkzeug/_internal.py", line 3, in <module>
[Sat Nov 02 00:20:53.824102 2024] [wsgi:error] [pid 24190] [remote 51.79.160.196:51806]     import logging
[Sat Nov 02 00:20:53.824128 2024] [wsgi:error] [pid 24190] [remote 51.79.160.196:51806]   File "/var/www/bdatalab/venv/lib/python3.12/site-packages/logging/__init__.py", line 618
[Sat Nov 02 00:20:53.824140 2024] [wsgi:error] [pid 24190] [remote 51.79.160.196:51806]     raise NotImplementedError, 'emit must be implemented '\\
[Sat Nov 02 00:20:53.824183 2024] [wsgi:error] [pid 24190] [remote 51.79.160.196:51806]                              ^
[Sat Nov 02 00:20:53.824191 2024] [wsgi:error] [pid 24190] [remote 51.79.160.196:51806] SyntaxError: invalid syntax
[Sat Nov 02 00:27:54.834925 2024] [wsgi:error] [pid 721] [remote 177.93.3.83:41732] mod_wsgi (pid=721): Failed to exec Python script file '/var/www/bdatalab/bdatalab.wsgi'.
[Sat Nov 02 00:27:54.835648 2024] [wsgi:error] [pid 721] [remote 177.93.3.83:41732] mod_wsgi (pid=721): Exception occurred processing WSGI script '/var/www/bdatalab/bdatalab.wsgi'.
[Sat Nov 02 00:27:54.845711 2024] [wsgi:error] [pid 721] [remote 177.93.3.83:41732] Traceback (most recent call last):
[Sat Nov 02 00:27:54.848976 2024] [wsgi:error] [pid 721] [remote 177.93.3.83:41732]   File "/var/www/bdatalab/bdatalab.wsgi", line 8, in <module>
[Sat Nov 02 00:27:54.848991 2024] [wsgi:error] [pid 721] [remote 177.93.3.83:41732]     from app import create_app
[Sat Nov 02 00:27:54.849004 2024] [wsgi:error] [pid 721] [remote 177.93.3.83:41732]   File "/var/www/bdatalab/app/__init__.py", line 2, in <module>
[Sat Nov 02 00:27:54.849009 2024] [wsgi:error] [pid 721] [remote 177.93.3.83:41732]     from flask import Flask
[Sat Nov 02 00:27:54.849018 2024] [wsgi:error] [pid 721] [remote 177.93.3.83:41732]   File "/var/www/bdatalab/venv/lib/python3.12/site-packages/flask/__init__.py", line 5, in <module>
[Sat Nov 02 00:27:54.849023 2024] [wsgi:error] [pid 721] [remote 177.93.3.83:41732]     from . import json as json
[Sat Nov 02 00:27:54.849031 2024] [wsgi:error] [pid 721] [remote 177.93.3.83:41732]   File "/var/www/bdatalab/venv/lib/python3.12/site-packages/flask/json/__init__.py", line 6, in <module>
[Sat Nov 02 00:27:54.849103 2024] [wsgi:error] [pid 721] [remote 177.93.3.83:41732]     from ..globals import current_app
[Sat Nov 02 00:27:54.849132 2024] [wsgi:error] [pid 721] [remote 177.93.3.83:41732]   File "/var/www/bdatalab/venv/lib/python3.12/site-packages/flask/globals.py", line 6, in <module>
[Sat Nov 02 00:27:54.849138 2024] [wsgi:error] [pid 721] [remote 177.93.3.83:41732]     from werkzeug.local import LocalProxy
[Sat Nov 02 00:27:54.849147 2024] [wsgi:error] [pid 721] [remote 177.93.3.83:41732]   File "/var/www/bdatalab/venv/lib/python3.12/site-packages/werkzeug/__init__.py", line 1, in <module>
[Sat Nov 02 00:27:54.849152 2024] [wsgi:error] [pid 721] [remote 177.93.3.83:41732]     from .serving import run_simple as run_simple
[Sat Nov 02 00:27:54.849161 2024] [wsgi:error] [pid 721] [remote 177.93.3.83:41732]   File "/var/www/bdatalab/venv/lib/python3.12/site-packages/werkzeug/serving.py", line 33, in <module>
[Sat Nov 02 00:27:54.849166 2024] [wsgi:error] [pid 721] [remote 177.93.3.83:41732]     from ._internal import _log
[Sat Nov 02 00:27:54.849175 2024] [wsgi:error] [pid 721] [remote 177.93.3.83:41732]   File "/var/www/bdatalab/venv/lib/python3.12/site-packages/werkzeug/_internal.py", line 3, in <module>
[Sat Nov 02 00:27:54.849180 2024] [wsgi:error] [pid 721] [remote 177.93.3.83:41732]     import logging
[Sat Nov 02 00:27:54.849198 2024] [wsgi:error] [pid 721] [remote 177.93.3.83:41732]   File "/var/www/bdatalab/venv/lib/python3.12/site-packages/logging/__init__.py", line 618
[Sat Nov 02 00:27:54.849210 2024] [wsgi:error] [pid 721] [remote 177.93.3.83:41732]     raise NotImplementedError, 'emit must be implemented '\\
[Sat Nov 02 00:27:54.849227 2024] [wsgi:error] [pid 721] [remote 177.93.3.83:41732]                              ^
[Sat Nov 02 00:27:54.849238 2024] [wsgi:error] [pid 721] [remote 177.93.3.83:41732] SyntaxError: invalid syntax
[Sat Nov 02 05:52:58.518577 2024] [core:error] [pid 777] [client 8.213.128.36:54014] AH10244: invalid URI path (/cgi-bin/.%2e/.%2e/.%2e/.%2e/.%2e/.%2e/.%2e/.%2e/.%2e/.%2e/bin/sh)
[Sat Nov 02 05:53:00.885827 2024] [core:error] [pid 2386] [client 8.213.128.36:54030] AH10244: invalid URI path (/cgi-bin/%%32%65%%32%65/%%32%65%%32%65/%%32%65%%32%65/%%32%65%%32%65/%%32%65%%32%65/%%32%65%%32%65/%%32%65%%32%65/bin/sh)
[Sat Nov 02 10:03:48.293668 2024] [core:error] [pid 5432] [client 67.60.128.211:54970] AH10244: invalid URI path (/cgi-bin/.%2e/.%2e/.%2e/.%2e/.%2e/.%2e/.%2e/.%2e/.%2e/.%2e/bin/sh)
[Sat Nov 02 10:04:02.904241 2024] [core:error] [pid 5434] [client 67.60.128.211:58668] AH10244: invalid URI path (/cgi-bin/%%32%65%%32%65/%%32%65%%32%65/%%32%65%%32%65/%%32%65%%32%65/%%32%65%%32%65/%%32%65%%32%65/%%32%65%%32%65/bin/sh)
